Workbook

Sheet Start here
A1: THE EXECUTOR'S DESK
A2: The Estate Ledger
A3: Inventory, ledger, claims, distribution and final accounting for one estate. Formulas only; no macros.
A5: 1. Fill in the estate details below. Shaded cells are yours to type in; white cells hold formulas and update by themselves.
A6: 2. Inventory tab: one row per asset, at date-of-death value. Mark how each passes (A, B or C, the same sort as the notebook).
A7: 3. Ledger tab: every transaction in the estate bank account, in date order. Money in on the left, money out on the right.
A8: 4. Tick the Receipt column for every outgoing amount. Rows without a receipt turn amber until you do.
A9: 5. Claims tab: every creditor claim as it arrives. Rows dated after the creditor window closes turn red.
A10: 6. Distribution tab: beneficiaries and their shares. The computed share updates from the ledger balance and your reserve.
A11: 7. Final accounting tab: print it. It pulls from the other tabs and is laid out the way courts and beneficiaries expect.
A12: 8. Delete the three gray italic example rows on each tab once you have entered your own.
A13: 9. Do not insert columns. Adding rows inside a table is fine; the totals cover 200 rows per table.
... A29: LEGEND
A30: Shaded cell | B30: Type here.
A31: White cell | B31: Formula. Leave it alone.
A32: Gray italic row | B32: Example. Delete it.
A34: Version 1.0, September 2026. General information, not legal or tax advice.

Sheet Inventory
A1: THE EXECUTOR'S DESK
A2: Inventory
A3: One row per asset at date-of-death value. A = passes by beneficiary designation. B = passes by ownership or trust. C = probate estate.
A5: TOTALS BY CATEGORY | D5: TOTALS BY HOW IT PASSES
A6: bank | B6: =SUMIF($A$19:$A$218,A6,$E$19:$E$218) | D6: A: beneficiary designation (not probate) | F6: =SUMIF($D$19:$D$218,"A",$E$19:$E$218)
A7: brokerage | B7: =SUMIF($A$19:$A$218,A7,$E$19:$E$218) | D7: B: joint / trust (not probate) | F7: =SUMIF($D$19:$D$218,"B",$E$19:$E$218)
A8: retirement | B8: =SUMIF($A$19:$A$218,A8,$E$19:$E$218) | D8: C: probate estate | F8: =SUMIF($D$19:$D$218,"C",$E$19:$E$218)
A9: life insurance | B9: =SUMIF($A$19:$A$218,A9,$E$19:$E$218) | D9: All assets | F9: =SUM($E$19:$E$218)
A10: real estate | B10: =SUMIF($A$19:$A$218,A10,$E$19:$E$218) | D10: Assets not yet valued (count) | F10: =SUMPRODUCT(($B$19:$B$218<>"")*($E$19:$E$218=""))
A11: vehicle | B11: =SUMIF($A$19:$A$218,A11,$E$19:$E$218)
A12: personal property | B12: =SUMIF($A$19:$A$218,A12,$E$19:$E$218)
A13: business | B13: =SUMIF($A$19:$A$218,A13,$E$19:$E$218)
A14: receivable | B14: =SUMIF($A$19:$A$218,A14,$E$19:$E$218)
A15: digital | B15: =SUMIF($A$19:$A$218,A15,$E$19:$E$218)
A16: Each row: pick a category, name the institution, mark A/B/C, enter the date-of-death value and where it came from.
A18: Category | B18: Institution / description | C18: Account last 4 | D18: Passes (A/B/C) | E18: Date-of-death value | F18: Source of value | G18: Status | H18: Notes
A19: bank | B19: First County Bank checking | C19: 4471 | D19: C | E19: 12480.22 | F19: statement | G19: valued | H19: Sole name, no POD. Moved to estate account 2026-04-02.
A20: retirement | B20: Fidelity IRA | C20: 9902 | D20: A | E20: 86310 | F20: statement | G20: located | H20: Beneficiary: the three children equally. Not probate.
A21: real estate | B21: 14 Elm St, Dayton OH | D21: C | E21: 214000 | F21: appraisal | G21: valued | H21: Date-of-death appraisal 2026-04-10, J. Ortiz, licensed.

Sheet Ledger
A1: THE EXECUTOR'S DESK
A2: Ledger
A3: Every transaction in the estate bank account. Reconcile to the statement monthly.
A5: Total money in | B5: =SUM($D$13:$D$212)
A6: Total money out | B6: =SUM($E$13:$E$212)
A7: Balance in estate account | B7: =B5-B6
A8: Outgoing rows without a receipt | B8: =COUNTIFS($E$13:$E$212,">0",$G$13:$G$212,"<>Yes")
A10: Money in goes in column D, money out in column E. Never both on one row. Receipt = Yes for every outgoing amount.
A12: Date | B12: Payee / payer | C12: Category | D12: Money in | E12: Money out | F12: Running balance | G12: Receipt? | H12: Notes
A13: 46114 | B13: First County Bank (transfer of sole-name checking) | C13: transfer in | D13: 12480.22 | F13: =IF(AND(D13="",E13=""),"",SUM($D$13:D13)-SUM($E$13:E13)) | G13: Yes | H13: Closing statement attached
A14: 46117 | B14: Dayton Daily News | C14: administration | E14: 145 | F14: =IF(AND(D14="",E14=""),"",SUM($D$13:D14)-SUM($E$13:E14)) | G14: Yes | H14: Notice to creditors, 3 runs
A15: 46121 | B15: Reimbursement to executor: death certificates | C15: reimbursement to executor | E15: 187.5 | F15: =IF(AND(D15="",E15=""),"",SUM($D$13:D15)-SUM($E$13:E15)) | G15: No | H15: Receipt in folder, not yet scanned
F16: =IF(AND(D16="",E16=""),"",SUM($D$13:D16)-SUM($E$13:E16))
F17: =IF(AND(D17="",E17=""),"",SUM($D$13:D17)-SUM($E$13:E17))
F18: =IF(AND(D18="",E18=""),"",SUM($D$13:D18)-SUM($E$13:E18))
F19: =IF(AND(D19="",E19=""),"",SUM($D$13:D19)-SUM($E$13:E19))
F20: =IF(AND(D20="",E20=""),"",SUM($D$13:D20)-SUM($E$13:E20))
F21: =IF(AND(D21="",E21=""),"",SUM($D$13:D21)-SUM($E$13:E21))
F22: =IF(AND(D22="",E22=""),"",SUM($D$13:D22)-SUM($E$13:E22))
F23: =IF(AND(D23="",E23=""),"",SUM($D$13:D23)-SUM($E$13:E23))
F24: =IF(AND(D24="",E24=""),"",SUM($D$13:D24)-SUM($E$13:E24))
F25: =IF(AND(D25="",E25=""),"",SUM($D$13:D25)-SUM($E$13:E25))
F26: =IF(AND(D26="",E26=""),"",SUM($D$13:D26)-SUM($E$13:E26))
F27: =IF(AND(D27="",E27=""),"",SUM($D$13:D27)-SUM($E$13:E27))
... F212: =IF(AND(D212="",E212=""),"",SUM($D$13:D212)-SUM($E$13:E212))

Sheet Claims
A1: THE EXECUTOR'S DESK
A2: Claims
A3: Every creditor claim as it arrives. Do not pay until the window closes and the estate is known to be solvent.
A5: Creditor window closes on | B5: =IF('Start here'!B25="","",'Start here'!B25) | C5: (set on the Start here tab; rows received after this date turn red)
A6: Total claimed | B6: =SUM($C$12:$C$211)
A7: Total allowed | B7: =SUM($G$12:$G$211)
A8: Total paid (from Ledger, category 'debt paid') | B8: =SUMIF(Ledger!$C$13:$C$212,"debt paid",Ledger!$E$13:$E$212)
A9: Claims still pending (count) | B9: =COUNTIF($F$12:$F$211,"pending")
A11: Creditor | B11: Date received | C11: Amount claimed | D11: Secured? | E11: Documentation received? | F11: Status | G11: Amount allowed | H11: Date paid | I11: Notes
A12: Capital One (card ending 2210) | B12: 46132 | C12: 3412.77 | D12: No | E12: Yes | F12: allowed | G12: 3412.77 | I12: Statement matches date-of-death balance
A13: Miami Valley Hospital | B13: 46144 | C13: 8900 | D13: No | E13: No | F13: disputed | G13: 0 | I13: Itemized bill requested 2026-05-03; Medicare not yet billed
A14: Late claim: Acme Collections | B14: 46295 | C14: 640 | D14: No | E14: No | F14: rejected | G14: 0 | I14: Received after window; rejection letter sent

Sheet Distribution
A1: THE EXECUTOR'S DESK
A2: Distribution
A3: Shares are computed from the ledger balance less the reserve. Nothing is distributed before the creditor window closes and taxes are reserved for.
A5: Balance in estate account | B5: =Ledger!B7
A6: Less: reserve for taxes and final costs | B6: ='Start here'!B26
A7: Less: specific gifts (dollar amounts below) | B7: =SUM($C$13:$C$62)
A8: Available for percentage shares | B8: =B5-B6-B7
A9: Percentages entered (should total 100%) | B9: =SUM($B$13:$B$62)
A10: Enter either a percentage or a specific gift amount per beneficiary, not both. Paid so far comes from your own records or the Ledger.
A12: Beneficiary | B12: Share % | C12: Specific gift ($) | D12: Computed share | E12: Paid so far | F12: Balance owed | G12: Receipt & release signed? | H12: Notes
A13: Anna Kowalski (daughter) | B13: 0.5 | D13: =IF(A13="","",IF(C13<>"",C13,$B$8*B13)) | E13: 0 | F13: =IF(A13="","",D13-N(E13)) | G13: No | H13: Address on file
A14: Mark Kowalski (son) | B14: 0.5 | D14: =IF(A14="","",IF(C14<>"",C14,$B$8*B14)) | E14: 0 | F14: =IF(A14="","",D14-N(E14)) | G14: No
A15: St. Luke's Parish (specific gift, will §4) | C15: 5000 | D15: =IF(A15="","",IF(C15<>"",C15,$B$8*B15)) | E15: 0 | F15: =IF(A15="","",D15-N(E15)) | G15: No | H15: Pay after window closes
D16: =IF(A16="","",IF(C16<>"",C16,$B$8*B16)) | F16: =IF(A16="","",D16-N(E16))
D17: =IF(A17="","",IF(C17<>"",C17,$B$8*B17)) | F17: =IF(A17="","",D17-N(E17))
D18: =IF(A18="","",IF(C18<>"",C18,$B$8*B18)) | F18: =IF(A18="","",D18-N(E18))
D19: =IF(A19="","",IF(C19<>"",C19,$B$8*B19)) | F19: =IF(A19="","",D19-N(E19))
D20: =IF(A20="","",IF(C20<>"",C20,$B$8*B20)) | F20: =IF(A20="","",D20-N(E20))
D21: =IF(A21="","",IF(C21<>"",C21,$B$8*B21)) | F21: =IF(A21="","",D21-N(E21))
D22: =IF(A22="","",IF(C22<>"",C22,$B$8*B22)) | F22: =IF(A22="","",D22-N(E22))
D23: =IF(A23="","",IF(C23<>"",C23,$B$8*B23)) | F23: =IF(A23="","",D23-N(E23))
D24: =IF(A24="","",IF(C24<>"",C24,$B$8*B24)) | F24: =IF(A24="","",D24-N(E24))
D25: =IF(A25="","",IF(C25<>"",C25,$B$8*B25)) | F25: =IF(A25="","",D25-N(E25))
D26: =IF(A26="","",IF(C26<>"",C26,$B$8*B26)) | F26: =IF(A26="","",D26-N(E26))
D27: =IF(A27="","",IF(C27<>"",C27,$B$8*B27)) | F27: =IF(A27="","",D27-N(E27))
... D62: =IF(A62="","",IF(C62<>"",C62,$B$8*B62)) | F62: =IF(A62="","",D62-N(E62))
A64: Total distributed per Ledger (category 'distribution') | B64: =SUMIF(Ledger!$C$13:$C$212,"distribution",Ledger!$E$13:$E$212)
A65: Total 'Paid so far' entered above | B65: =SUM($E$13:$E$62)
A66: Difference (should be zero) | B66: =B64-B65

Sheet Final accounting
A1: THE EXECUTOR'S DESK
A2: Final accounting
A3: Print this page. Every number pulls from the other tabs.
A5: Estate of | B5: =IF('Start here'!B20="","",'Start here'!B20)
A6: Date of death | B6: =IF('Start here'!B21="","",'Start here'!B21)
A7: Court and case number | B7: =IF('Start here'!B23="","",'Start here'!B23)
A8: Personal representative | B8: =IF('Start here'!B24="","",'Start here'!B24)
A10: I. Inventory at date of death
A11: Probate estate (Inventory, C) | B11: =Inventory!F8
A12: Non-probate: beneficiary designations (A) | B12: =Inventory!F6
A13: Non-probate: joint and trust (B) | B13: =Inventory!F7
A14: Total assets at date of death | B14: =SUM(B11:B13)
A16: II. Receipts into the estate account
A17: Transfers of inventory assets into the estate account | B17: =SUMIF(Ledger!$C$13:$C$212,"transfer in",Ledger!$D$13:$D$212)
A18: Proceeds of sales | B18: =SUMIF(Ledger!$C$13:$C$212,"sale proceeds",Ledger!$D$13:$D$212)
A19: Income: interest | B19: =SUMIF(Ledger!$C$13:$C$212,"income-interest",Ledger!$D$13:$D$212)
A20: Income: dividends | B20: =SUMIF(Ledger!$C$13:$C$212,"income-dividend",Ledger!$D$13:$D$212)
A21: Income: other | B21: =SUMIF(Ledger!$C$13:$C$212,"income-other",Ledger!$D$13:$D$212)
A22: Total receipts | B22: =SUM(B17:B21)
A24: III. Disbursements
A25: Funeral | B25: =SUMIF(Ledger!$C$13:$C$212,"funeral",Ledger!$E$13:$E$212)
A26: Administration | B26: =SUMIF(Ledger!$C$13:$C$212,"administration",Ledger!$E$13:$E$212)
A27: Legal | B27: =SUMIF(Ledger!$C$13:$C$212,"legal",Ledger!$E$13:$E$212)
A28: Accounting | B28: =SUMIF(Ledger!$C$13:$C$212,"accounting",Ledger!$E$13:$E$212)
A29: Tax | B29: =SUMIF(Ledger!$C$13:$C$212,"tax",Ledger!$E$13:$E$212)
A30: Debts and claims paid | B30: =SUMIF(Ledger!$C$13:$C$212,"debt paid",Ledger!$E$13:$E$212)
A31: Reimbursement to executor | B31: =SUMIF(Ledger!$C$13:$C$212,"reimbursement to executor",Ledger!$E$13:$E$212)
A32: Total disbursements before distributions | B32: =SUM(B25:B31)
A34: IV. Distributions to beneficiaries
A35: Distributions paid (Ledger) | B35: =SUMIF(Ledger!$C$13:$C$212,"distribution",Ledger!$E$13:$E$212)
A37: V. Reconciliation
A38: Total receipts (II) | B38: =B22
A39: Less total disbursements (III) | B39: =B32
A40: Less distributions (IV) | B40: =B35
A41: Balance remaining in estate account | B41: =B38-B39-B40
A42: Ledger running balance (should match) | B42: =Ledger!B7
A43: Difference (should be zero) | B43: =B41-B42
A45: VI. Still to do
A46: Assets in inventory not yet valued (count) | B46: =Inventory!F10
A47: Claims still pending (count) | B47: =Claims!B9
...
